Workbook

Sheet Resumen
A1: Diccionario de datos · CaféDirecto
A2: Base de datos PostgreSQL 16 (Railway) · esquema: server/src/schema.sql · versión 3.1 (auditoría) · 28 de octubre de 2026
A3: Hojas: Diccionario (campo por campo) · Relaciones (llaves foráneas) · Índices · Valores (dominios permitidos). PK = llave primaria, FK = llave foránea, UK = valor único.
A5: N.º | B5: Tabla | C5: Módulo | D5: Descripción | E5: N.º de campos | F5: Llaves foráneas
A6: 1 | B6: users | C6: Cuentas | D6: Cuentas de usuario: caficultores y compradores. | E6: =COUNTIF(Diccionario!$A:$A,B6) -> 11 | F6: =COUNTIFS(Diccionario!$A:$A,B6,Diccionario!$F:$F,"*FK*") -> 1
A7: 2 | B7: farms | C7: Cuentas | D7: Perfil de la finca del caficultor (1 a 1 con users). | E7: =COUNTIF(Diccionario!$A:$A,B7) -> 18 | F7: =COUNTIFS(Diccionario!$A:$A,B7,Diccionario!$F:$F,"*FK*") -> 2
A8: 3 | B8: buyers | C8: Cuentas | D8: Perfil de la empresa del comprador (1 a 1 con users). | E8: =COUNTIF(Diccionario!$A:$A,B8) -> 12 | F8: =COUNTIFS(Diccionario!$A:$A,B8,Diccionario!$F:$F,"*FK*") -> 2
A9: 4 | B9: password_resets | C9: Cuentas | D9: Código vigente para recuperar la contraseña (uno por usuario). | E9: =COUNTIF(Diccionario!$A:$A,B9) -> 5 | F9: =COUNTIFS(Diccionario!$A:$A,B9,Diccionario!$F:$F,"*FK*") -> 1
A10: 5 | B10: images | C10: Archivos | D10: Fotos subidas por los usuarios (perfil, finca, lotes, chat), guardadas en la base. | E10: =COUNTIF(Diccionario!$A:$A,B10) -> 5 | F10: =COUNTIFS(Diccionario!$A:$A,B10,Diccionario!$F:$F,"*FK*") -> 0
A11: 6 | B11: lots | C11: Catálogo | D11: Lotes de café publicados por los caficultores. | E11: =COUNTIF(Diccionario!$A:$A,B11) -> 14 | F11: =COUNTIFS(Diccionario!$A:$A,B11,Diccionario!$F:$F,"*FK*") -> 2
A12: 7 | B12: lot_views | C12: Catálogo | D12: Compradores que abrieron un lote; base de los avisos de interés. | E12: =COUNTIF(Diccionario!$A:$A,B12) -> 6 | F12: =COUNTIFS(Diccionario!$A:$A,B12,Diccionario!$F:$F,"*FK*") -> 2
A13: 8 | B13: conversations | C13: Chat | D13: Chat entre un caficultor y un comprador (uno por pareja). | E13: =COUNTIF(Diccionario!$A:$A,B13) -> 8 | F13: =COUNTIFS(Diccionario!$A:$A,B13,Diccionario!$F:$F,"*FK*") -> 3
A14: 9 | B14: messages | C14: Chat | D14: Mensajes del chat: texto traducido, foto, cotización, acuerdo o aviso del sistema. | E14: =COUNTIF(Diccionario!$A:$A,B14) -> 15 | F14: =COUNTIFS(Diccionario!$A:$A,B14,Diccionario!$F:$F,"*FK*") -> 4
A15: 10 | B15: agreements | C15: Acuerdos | D15: Acuerdos de compra registrados (por cotización o por subasta). | E15: =COUNTIF(Diccionario!$A:$A,B15) -> 16 | F15: =COUNTIFS(Diccionario!$A:$A,B15,Diccionario!$F:$F,"*FK*") -> 4
A16: 11 | B16: ratings | C16: Acuerdos | D16: Calificación mutua al terminar un acuerdo (una por persona y acuerdo). | E16: =COUNTIF(Diccionario!$A:$A,B16) -> 7 | F16: =COUNTIFS(Diccionario!$A:$A,B16,Diccionario!$F:$F,"*FK*") -> 2
A17: 12 | B17: quality_reports | C17: Acuerdos | D17: Reporte de calidad que emite el comprador tras la entrega (RF-22). | E17: =COUNTIF(Diccionario!$A:$A,B17) -> 11 | F17: =COUNTIFS(Diccionario!$A:$A,B17,Diccionario!$F:$F,"*FK*") -> 3
... A22: 17 | B22: market_snapshots | C22: Mercado | D22: Registro diario de precios del café para el histórico. | E22: =COUNTIF(Diccionario!$A:$A,B22) -> 5 | F22: =COUNTIFS(Diccionario!$A:$A,B22,Diccionario!$F:$F,"*FK*") -> 0
D23: Total | E23: =SUM(E6:E22) -> 171 | F23: =SUM(F6:F22) -> 34
A25: Notas
A26: • Las tablas se crean solas al arrancar el servidor (CREATE TABLE IF NOT EXISTS): no hay que ejecutar scripts a mano.
A27: • Los textos que escribe una persona (historia, descripción, comentarios) se guardan en español e inglés (_es / _en), traducidos automáticamente.
A28: • Los precios en US$ son por libra de café verde; los precios en COP son por carga de 125 kg de café pergamino seco.
A29: • Un saco equivale a 70 kg de café verde.
A30: • «(lógica)» en Referencia indica un vínculo que se respeta en el código pero no tiene FOREIGN KEY en la base.

Sheet Diccionario
A1: Tabla | B1: Campo | C1: Tipo de dato | D1: ¿Acepta nulo? | E1: Valor por defecto | F1: Llave | G1: Referencia | H1: Restricciones / reglas | I1: Descripción | J1: Ejemplo
A2: users | B2: id | C2: SERIAL | D2: No | E2: autoincremental | F2: PK | I2: Identificador del usuario. | J2: 12
A3: users | B3: email | C3: TEXT | D3: No | F3: UK | H3: Único; se guarda en minúsculas | I3: Correo con el que inicia sesión. | J3: luz@finca.co
A4: users | B4: password_hash | C4: TEXT | D4: No | H4: Hash bcrypt (costo 10); clave nueva: 8+ con letras y números | I4: Contraseña cifrada; nunca se guarda en texto plano. | J4: $2a$10$…
A5: users | B5: role | C5: TEXT | D5: No | H5: IN ('farmer','buyer') | I5: Rol: caficultor o comprador. | J5: farmer
A6: users | B6: name | C6: TEXT | D6: No | H6: Máx. 120 caracteres | I6: Nombre de la persona. | J6: Luz Marina Rojas
A7: users | B7: phone | C7: TEXT | D7: Sí | H7: Máx. 40 caracteres | I7: Celular (opcional). | J7: +57 310 000 0000
A8: users | B8: lang | C8: TEXT | D8: No | E8: 'es' | H8: IN ('es','en') | I8: Idioma de la app; los mensajes recibidos se traducen a este idioma. | J8: es
A9: users | B9: photo_id | C9: INTEGER | D9: Sí | F9: FK | G9: images.id | H9: ON DELETE SET NULL | I9: Foto de perfil. | J9: 5
A10: users | B10: created_at | C10: TIMESTAMPTZ | D10: No | E10: now() | I10: Fecha de registro. | J10: 2026-10-21 10:15:00-05
A11: users | B11: deleted_at | C11: TIMESTAMPTZ | D11: Sí | I11: Fecha en que se eliminó la cuenta (queda anónima si tiene acuerdos). | J11: NULL
A12: users | B12: token_version | C12: INTEGER | D12: No | E12: 0 | I12: Sube al cambiar la contraseña; invalida las sesiones abiertas. | J12: 0
A13: farms | B13: user_id | C13: INTEGER | D13: No | F13: PK, FK | G13: users.id | H13: ON DELETE CASCADE | I13: Caficultor dueño de la finca. | J13: 12
A14: farms | B14: name | C14: TEXT | D14: No | E14: '' | H14: Máx. 120 | I14: Nombre de la finca. | J14: La Esperanza
A15: farms | B15: region | C15: TEXT | D15: No | E15: '' | H15: Máx. 80 | I15: Departamento. | J15: Huila
A16: farms | B16: municipality | C16: TEXT | D16: No | E16: '' | H16: Máx. 80 | I16: Municipio. | J16: Pitalito
A17: farms | B17: altitude | C17: INTEGER | D17: No | E17: 0 | H17: CHECK 0–6000 | I17: Altitud en metros sobre el nivel del mar. | J17: 1750
A18: farms | B18: hectares | C18: NUMERIC | D18: No | E18: 0 | I18: Tamaño en hectáreas. | J18: 4.5
A19: farms | B19: varieties | C19: TEXT[] | D19: No | E19: '{}' | H19: Máx. 20 | I19: Variedades cultivadas. | J19: {Caturra,Pink Bourbon}
A20: farms | B20: processes | C20: TEXT[] | D20: No | E20: '{}' | H20: lavado / honey / natural | I20: Procesos poscosecha. | J20: {lavado,honey}
A21: farms | B21: sca | C21: NUMERIC | D21: No | E21: 0 | H21: CHECK 0–100 | I21: Puntaje SCA típico de la finca. | J21: 86.5
A22: farms | B22: notes | C22: TEXT[] | D22: No | E22: '{}' | I22: Notas de catación. | J22: {panela,chocolate}
A23: farms | B23: since | C23: INTEGER | D23: Sí | I23: Año desde el que cultiva. | J23: 1998
A24: farms | B24: story_es | C24: TEXT | D24: No | E24: '' | I24: Historia de la finca en español (traducida automáticamente). | J24: Somos tres generaciones…
A25: farms | B25: story_en | C25: TEXT | D25: No | E25: '' | I25: Historia en inglés. | J25: We are three generations…
A26: farms | B26: quote_es | C26: TEXT | D26: No | E26: '' | I26: Frase destacada en español. | J26: El café se cuida con amor
A27: farms | B27: quote_en | C27: TEXT | D27: No | E27: '' | I27: Frase destacada en inglés. | J27: Coffee is grown with love
A28: farms | B28: certifications | C28: TEXT | D28: No | E28: '' | H28: Una por línea; máx. 2000 | I28: Certificaciones (solo lectura). | J28: Rainforest Alliance
A29: farms | B29: cover_id | C29: INTEGER | D29: Sí | F29: FK | G29: images.id | H29: ON DELETE SET NULL | I29: Foto de portada. | J29: 8
A30: farms | B30: gallery | C30: INTEGER[] | D30: No | E30: '{}' | G30: images.id (lógica) | H30: Máx. 12 | I30: Ids de las fotos de la galería. | J30: {9,10,11}
A31: buyers | B31: user_id | C31: INTEGER | D31: No | F31: PK, FK | G31: users.id | H31: ON DELETE CASCADE | I31: Comprador dueño del perfil. | J31: 15
A32: buyers | B32: company | C32: TEXT | D32: No | E32: '' | H32: Máx. 120 | I32: Empresa o tostadora. | J32: Nordlicht Roasters
A33: buyers | B33: city | C33: TEXT | D33: No | E33: '' | H33: Máx. 80 | I33: Ciudad. | J33: Hamburgo
A34: buyers | B34: country | C34: TEXT | D34: No | E34: '' | H34: Máx. 80 | I34: País. | J34: Alemania
A35: buyers | B35: type | C35: TEXT | D35: No | E35: '' | H35: Máx. 80 | I35: Tipo de comprador. | J35: Tostador de especialidad
A36: buyers | B36: volume | C36: TEXT | D36: No | E36: '' | H36: Máx. 80 | I36: Volumen que compra. | J36: 200 sacos/año
A37: buyers | B37: since | C37: INTEGER | D37: Sí | I37: Año desde el que compra café. | J37: 2015
A38: buyers | B38: about_es | C38: TEXT | D38: No | E38: '' | I38: Descripción en español. | J38: Tostamos en pequeños lotes…
A39: buyers | B39: about_en | C39: TEXT | D39: No | E39: '' | I39: Descripción en inglés. | J39: We roast in small batches…
A40: buyers | B40: looking_es | C40: TEXT | D40: No | E40: '' | I40: Qué busca, en español. | J40: Lavados de 86+ puntos
...

Sheet Relaciones
A1: Tabla padre | B1: Tabla hija | C1: Cardinalidad | D1: Llave foránea | E1: Al borrar el padre | F1: Significado
A2: users | B2: farms | C2: 1 : 0..1 | D2: farms.user_id → users.id | E2: CASCADE | F2: Cada caficultor tiene un perfil de finca.
A3: users | B3: buyers | C3: 1 : 0..1 | D3: buyers.user_id → users.id | E3: CASCADE | F3: Cada comprador tiene un perfil de empresa.
A4: users | B4: password_resets | C4: 1 : 0..1 | D4: password_resets.user_id → users.id | E4: CASCADE | F4: Un código vigente por usuario.
A5: images | B5: users | C5: 1 : N | D5: users.photo_id → images.id | E5: SET NULL | F5: Foto de perfil.
A6: images | B6: farms / buyers | C6: 1 : N | D6: cover_id → images.id | E6: SET NULL | F6: Portadas.
A7: users | B7: lots | C7: 1 : N | D7: lots.farmer_id → users.id | E7: CASCADE | F7: Un caficultor publica muchos lotes.
A8: lots | B8: lot_views | C8: 1 : N | D8: lot_views.lot_id → lots.id | E8: CASCADE | F8: Vistas de compradores.
A9: users | B9: lot_views | C9: 1 : N | D9: lot_views.buyer_id → users.id | E9: CASCADE | F9: Lotes que vio un comprador.
A10: users | B10: conversations | C10: 1 : N (×2) | D10: farmer_id / buyer_id → users.id | E10: CASCADE | F10: Un chat por pareja caficultor–comprador.
A11: lots | B11: conversations | C11: 1 : N | D11: conversations.lot_id → lots.id | E11: SET NULL | F11: Lote del que se habla.
A12: conversations | B12: messages | C12: 1 : N | D12: messages.conversation_id → conversations.id | E12: CASCADE | F12: Mensajes del chat.
... A26: users | B26: notifications | C26: 1 : N | D26: notifications.user_id → users.id | E26: CASCADE | F26: Avisos del usuario.

Sheet Índices
A1: Tabla | B1: Índice | C1: Columnas | D1: Tipo | E1: Para qué
A2: users | B2: users_email_key | C2: email | D2: UNIQUE | E2: Inicio de sesión por correo.
A3: conversations | B3: conversations_farmer_id_buyer_id_key | C3: farmer_id, buyer_id | D3: UNIQUE | E3: Un chat por pareja.
A4: conversations | B4: conversations_buyer_idx | C4: buyer_id, updated_at DESC | E4: Lista de chats del comprador.
A5: conversations | B5: conversations_farmer_idx | C5: farmer_id, updated_at DESC | E5: Lista de chats del caficultor.
A6: messages | B6: messages_conv_idx | C6: conversation_id, id | E6: Mensajes nuevos de un chat (id > último).
A7: lots | B7: lots_farmer_idx | C7: farmer_id (activos) | D7: Parcial | E7: Lotes de un caficultor.
A8: lots | B8: lots_active_created_idx | C8: created_at DESC (activos con sacos) | D8: Parcial | E8: Catálogo de Explorar.
A9: agreements | B9: agreements_code_key | C9: code | D9: UNIQUE | E9: Código CD-AAAA-####.
A10: agreements | B10: agreements_farmer_idx | C10: farmer_id, created_at DESC | E10: Acuerdos del caficultor.
A11: agreements | B11: agreements_buyer_idx | C11: buyer_id, created_at DESC | E11: Acuerdos del comprador.
A12: ratings | B12: ratings_by_user_idx | C12: by_user_id | E12: Reputación.
A13: disputes | B13: disputes_open_idx | C13: agreement_id (abiertas) | D13: UNIQUE parcial | E13: Máx. una disputa abierta por acuerdo.
A14: auctions | B14: auctions_open_lot_idx | C14: lot_id (abiertas) | D14: UNIQUE parcial | E14: Máx. una subasta abierta por lote.
A15: auctions | B15: auctions_farmer_idx | C15: farmer_id, id DESC | E15: Mis subastas.
A16: auctions | B16: auctions_open_ends_idx | C16: ends_at (abiertas) | D16: Parcial | E16: Proceso que cierra subastas cada minuto.
A17: bids | B17: bids_auction_idx | C17: auction_id, price_lb DESC | E17: Oferta más alta.
A18: bids | B18: bids_buyer_idx | C18: buyer_id | E18: Subastas en las que pujé.
A19: notifications | B19: notifications_user_idx | C19: user_id, id DESC | E19: Lista de avisos.
A20: notifications | B20: notifications_unread_idx | C20: user_id (sin leer) | D20: Parcial | E20: Contador de la campanita.
A21: lot_views | B21: lot_views_buyer_idx | C21: buyer_id | E21: Borrado de cuenta y consultas por comprador.
A22: images | B22: images_owner_idx | C22: owner_id | E22: Verificar que la foto sea de quien la usa.

Sheet Valores
A1: Campo | B1: Valor | C1: Significado
A2: users.role | B2: farmer | C2: Caficultor
A3: users.role | B3: buyer | C3: Comprador
A4: users.lang | B4: es | C4: Español
A5: users.lang | B5: en | C5: Inglés
A6: lots.process | B6: lavado | C6: Lavado
A7: lots.process | B7: honey | C7: Honey
A8: lots.process | B8: natural | C8: Natural
A9: messages.type | B9: text | C9: Texto (con traducción)
A10: messages.type | B10: photo | C10: Foto
A11: messages.type | B11: quote | C11: Cotización
A12: messages.type | B12: agreement | C12: Tarjeta de acuerdo registrado
... A50: notifications.type | B50: rating_new | C50: Te calificaron
